<?xml version="1.0" encoding="UTF-8"?>
<!-- Generated by org.testng.reporters.JUnitReportReporter -->
<testsuite hostname="haile" failures="0" tests="18" name="testModel.CauHoi_DeThiTest" time="0.024" errors="4" timestamp="2021-12-05T23:18:10 ICT" skipped="0">
  <testcase classname="testModel.CauHoi_DeThiTest" name="isTrangThaiTest_TC_08" time="0.001"/>
  <system-out/>
  <testcase classname="testModel.CauHoi_DeThiTest" name="getDeThi_idTest_TC_06" time="0.001"/>
  <system-out/>
  <testcase classname="testModel.CauHoi_DeThiTest" name="setTrangThaiTest_TC_17" time="0.000"/>
  <system-out/>
  <testcase classname="testModel.CauHoi_DeThiTest" name="setDeThi_idTest_TC_16" time="0.001"/>
  <system-out/>
  <testcase classname="testModel.CauHoi_DeThiTest" name="getCauTraLoiTest_TC_03" time="0.001"/>
  <system-out/>
  <testcase classname="testModel.CauHoi_DeThiTest" name="getCauHoi_idTest_TC_02" time="0.001"/>
  <system-out/>
  <testcase classname="testModel.CauHoi_DeThiTest" name="getCauTraLoiTest_TC_04" time="0.001"/>
  <system-out/>
  <testcase classname="testModel.CauHoi_DeThiTest" name="setCauTraLoiTest_TC_11" time="0.001">
    <error message="
Method CauHoi_DeThiTest.setCauTraLoiTest_TC_11()[pri:0, instance:testModel.CauHoi_DeThiTest@4961f6af] should have thrown an exception of type class java.lang.Exception" type="org.testng.TestException">
      <![CDATA[org.testng.TestException: 
Method CauHoi_DeThiTest.setCauTraLoiTest_TC_11()[pri:0, instance:testModel.CauHoi_DeThiTest@4961f6af] should have thrown an exception of type class java.lang.Exception
at org.testng.internal.ExpectedExceptionsHolder.noException(ExpectedExceptionsHolder.java:82)
at org.testng.internal.TestInvoker.considerExceptions(TestInvoker.java:749)
at org.testng.internal.TestInvoker.invokeMethod(TestInvoker.java:634)
at org.testng.internal.TestInvoker.invokeTestMethod(TestInvoker.java:173)
at org.testng.internal.MethodRunner.runInSequence(MethodRunner.java:46)
at org.testng.internal.TestInvoker$MethodInvocationAgent.invoke(TestInvoker.java:824)
at org.testng.internal.TestInvoker.invokeTestMethods(TestInvoker.java:146)
at org.testng.internal.TestMethodWorker.invokeTestMethods(TestMethodWorker.java:146)
at org.testng.internal.TestMethodWorker.run(TestMethodWorker.java:128)
at java.base/java.util.ArrayList.forEach(ArrayList.java:1511)
at org.testng.TestRunner.privateRun(TestRunner.java:794)
at org.testng.TestRunner.run(TestRunner.java:596)
at org.testng.SuiteRunner.runTest(SuiteRunner.java:377)
at org.testng.SuiteRunner.runSequentially(SuiteRunner.java:371)
at org.testng.SuiteRunner.privateRun(SuiteRunner.java:332)
at org.testng.SuiteRunner.run(SuiteRunner.java:276)
at org.testng.SuiteRunnerWorker.runSuite(SuiteRunnerWorker.java:53)
at org.testng.SuiteRunnerWorker.run(SuiteRunnerWorker.java:96)
at org.testng.TestNG.runSuitesSequentially(TestNG.java:1212)
at org.testng.TestNG.runSuitesLocally(TestNG.java:1134)
at org.testng.TestNG.runSuites(TestNG.java:1063)
at org.testng.TestNG.run(TestNG.java:1031)
at org.testng.remote.AbstractRemoteTestNG.run(AbstractRemoteTestNG.java:115)
at org.testng.remote.RemoteTestNG.initAndRun(RemoteTestNG.java:251)
at org.testng.remote.RemoteTestNG.main(RemoteTestNG.java:77)
]]>
    </error>
  </testcase> <!-- setCauTraLoiTest_TC_11 -->
  <system-out/>
  <testcase classname="testModel.CauHoi_DeThiTest" name="setCauHoi_idTest_TC_10" time="0.001"/>
  <system-out/>
  <testcase classname="testModel.CauHoi_DeThiTest" name="setCauHoi_idTest_TC_09" time="0.001">
    <error message="
Method CauHoi_DeThiTest.setCauHoi_idTest_TC_09()[pri:0, instance:testModel.CauHoi_DeThiTest@4961f6af] should have thrown an exception of type class java.lang.Exception" type="org.testng.TestException">
      <![CDATA[org.testng.TestException: 
Method CauHoi_DeThiTest.setCauHoi_idTest_TC_09()[pri:0, instance:testModel.CauHoi_DeThiTest@4961f6af] should have thrown an exception of type class java.lang.Exception
at org.testng.internal.ExpectedExceptionsHolder.noException(ExpectedExceptionsHolder.java:82)
at org.testng.internal.TestInvoker.considerExceptions(TestInvoker.java:749)
at org.testng.internal.TestInvoker.invokeMethod(TestInvoker.java:634)
at org.testng.internal.TestInvoker.invokeTestMethod(TestInvoker.java:173)
at org.testng.internal.MethodRunner.runInSequence(MethodRunner.java:46)
at org.testng.internal.TestInvoker$MethodInvocationAgent.invoke(TestInvoker.java:824)
at org.testng.internal.TestInvoker.invokeTestMethods(TestInvoker.java:146)
at org.testng.internal.TestMethodWorker.invokeTestMethods(TestMethodWorker.java:146)
at org.testng.internal.TestMethodWorker.run(TestMethodWorker.java:128)
at java.base/java.util.ArrayList.forEach(ArrayList.java:1511)
at org.testng.TestRunner.privateRun(TestRunner.java:794)
at org.testng.TestRunner.run(TestRunner.java:596)
at org.testng.SuiteRunner.runTest(SuiteRunner.java:377)
at org.testng.SuiteRunner.runSequentially(SuiteRunner.java:371)
at org.testng.SuiteRunner.privateRun(SuiteRunner.java:332)
at org.testng.SuiteRunner.run(SuiteRunner.java:276)
at org.testng.SuiteRunnerWorker.runSuite(SuiteRunnerWorker.java:53)
at org.testng.SuiteRunnerWorker.run(SuiteRunnerWorker.java:96)
at org.testng.TestNG.runSuitesSequentially(TestNG.java:1212)
at org.testng.TestNG.runSuitesLocally(TestNG.java:1134)
at org.testng.TestNG.runSuites(TestNG.java:1063)
at org.testng.TestNG.run(TestNG.java:1031)
at org.testng.remote.AbstractRemoteTestNG.run(AbstractRemoteTestNG.java:115)
at org.testng.remote.RemoteTestNG.initAndRun(RemoteTestNG.java:251)
at org.testng.remote.RemoteTestNG.main(RemoteTestNG.java:77)
]]>
    </error>
  </testcase> <!-- setCauHoi_idTest_TC_09 -->
  <system-out/>
  <testcase classname="testModel.CauHoi_DeThiTest" name="getCauHoi_idTest_TC_01" time="0.007"/>
  <system-out/>
  <testcase classname="testModel.CauHoi_DeThiTest" name="setCauTraLoiTest_TC_12" time="0.001"/>
  <system-out/>
  <testcase classname="testModel.CauHoi_DeThiTest" name="setTrangThaiTest_TC_18" time="0.001"/>
  <system-out/>
  <testcase classname="testModel.CauHoi_DeThiTest" name="isTrangThaiTest_TC_07" time="0.003"/>
  <system-out/>
  <testcase classname="testModel.CauHoi_DeThiTest" name="setCauTraLoiTest_TC_13" time="0.001">
    <error message="
Method CauHoi_DeThiTest.setCauTraLoiTest_TC_13()[pri:0, instance:testModel.CauHoi_DeThiTest@4961f6af] should have thrown an exception of type class java.lang.Exception" type="org.testng.TestException">
      <![CDATA[org.testng.TestException: 
Method CauHoi_DeThiTest.setCauTraLoiTest_TC_13()[pri:0, instance:testModel.CauHoi_DeThiTest@4961f6af] should have thrown an exception of type class java.lang.Exception
at org.testng.internal.ExpectedExceptionsHolder.noException(ExpectedExceptionsHolder.java:82)
at org.testng.internal.TestInvoker.considerExceptions(TestInvoker.java:749)
at org.testng.internal.TestInvoker.invokeMethod(TestInvoker.java:634)
at org.testng.internal.TestInvoker.invokeTestMethod(TestInvoker.java:173)
at org.testng.internal.MethodRunner.runInSequence(MethodRunner.java:46)
at org.testng.internal.TestInvoker$MethodInvocationAgent.invoke(TestInvoker.java:824)
at org.testng.internal.TestInvoker.invokeTestMethods(TestInvoker.java:146)
at org.testng.internal.TestMethodWorker.invokeTestMethods(TestMethodWorker.java:146)
at org.testng.internal.TestMethodWorker.run(TestMethodWorker.java:128)
at java.base/java.util.ArrayList.forEach(ArrayList.java:1511)
at org.testng.TestRunner.privateRun(TestRunner.java:794)
at org.testng.TestRunner.run(TestRunner.java:596)
at org.testng.SuiteRunner.runTest(SuiteRunner.java:377)
at org.testng.SuiteRunner.runSequentially(SuiteRunner.java:371)
at org.testng.SuiteRunner.privateRun(SuiteRunner.java:332)
at org.testng.SuiteRunner.run(SuiteRunner.java:276)
at org.testng.SuiteRunnerWorker.runSuite(SuiteRunnerWorker.java:53)
at org.testng.SuiteRunnerWorker.run(SuiteRunnerWorker.java:96)
at org.testng.TestNG.runSuitesSequentially(TestNG.java:1212)
at org.testng.TestNG.runSuitesLocally(TestNG.java:1134)
at org.testng.TestNG.runSuites(TestNG.java:1063)
at org.testng.TestNG.run(TestNG.java:1031)
at org.testng.remote.AbstractRemoteTestNG.run(AbstractRemoteTestNG.java:115)
at org.testng.remote.RemoteTestNG.initAndRun(RemoteTestNG.java:251)
at org.testng.remote.RemoteTestNG.main(RemoteTestNG.java:77)
]]>
    </error>
  </testcase> <!-- setCauTraLoiTest_TC_13 -->
  <system-out/>
  <testcase classname="testModel.CauHoi_DeThiTest" name="setCauTraLoiTest_TC_14" time="0.000"/>
  <system-out/>
  <testcase classname="testModel.CauHoi_DeThiTest" name="getDeThi_idTest_TC_05" time="0.001"/>
  <system-out/>
  <testcase classname="testModel.CauHoi_DeThiTest" name="setDeThi_idTest_TC_15" time="0.001">
    <error message="
Method CauHoi_DeThiTest.setDeThi_idTest_TC_15()[pri:0, instance:testModel.CauHoi_DeThiTest@4961f6af] should have thrown an exception of type class java.lang.Exception" type="org.testng.TestException">
      <![CDATA[org.testng.TestException: 
Method CauHoi_DeThiTest.setDeThi_idTest_TC_15()[pri:0, instance:testModel.CauHoi_DeThiTest@4961f6af] should have thrown an exception of type class java.lang.Exception
at org.testng.internal.ExpectedExceptionsHolder.noException(ExpectedExceptionsHolder.java:82)
at org.testng.internal.TestInvoker.considerExceptions(TestInvoker.java:749)
at org.testng.internal.TestInvoker.invokeMethod(TestInvoker.java:634)
at org.testng.internal.TestInvoker.invokeTestMethod(TestInvoker.java:173)
at org.testng.internal.MethodRunner.runInSequence(MethodRunner.java:46)
at org.testng.internal.TestInvoker$MethodInvocationAgent.invoke(TestInvoker.java:824)
at org.testng.internal.TestInvoker.invokeTestMethods(TestInvoker.java:146)
at org.testng.internal.TestMethodWorker.invokeTestMethods(TestMethodWorker.java:146)
at org.testng.internal.TestMethodWorker.run(TestMethodWorker.java:128)
at java.base/java.util.ArrayList.forEach(ArrayList.java:1511)
at org.testng.TestRunner.privateRun(TestRunner.java:794)
at org.testng.TestRunner.run(TestRunner.java:596)
at org.testng.SuiteRunner.runTest(SuiteRunner.java:377)
at org.testng.SuiteRunner.runSequentially(SuiteRunner.java:371)
at org.testng.SuiteRunner.privateRun(SuiteRunner.java:332)
at org.testng.SuiteRunner.run(SuiteRunner.java:276)
at org.testng.SuiteRunnerWorker.runSuite(SuiteRunnerWorker.java:53)
at org.testng.SuiteRunnerWorker.run(SuiteRunnerWorker.java:96)
at org.testng.TestNG.runSuitesSequentially(TestNG.java:1212)
at org.testng.TestNG.runSuitesLocally(TestNG.java:1134)
at org.testng.TestNG.runSuites(TestNG.java:1063)
at org.testng.TestNG.run(TestNG.java:1031)
at org.testng.remote.AbstractRemoteTestNG.run(AbstractRemoteTestNG.java:115)
at org.testng.remote.RemoteTestNG.initAndRun(RemoteTestNG.java:251)
at org.testng.remote.RemoteTestNG.main(RemoteTestNG.java:77)
]]>
    </error>
  </testcase> <!-- setDeThi_idTest_TC_15 -->
  <system-out/>
</testsuite> <!-- testModel.CauHoi_DeThiTest -->
