<?xml version="1.0" encoding="UTF-8"?>
<!-- Generated by org.testng.reporters.JUnitReportReporter -->
<testsuite hostname="haile" failures="1" tests="23" name="testModel.AnswerTest" time="0.031" errors="2" timestamp="2021-12-05T22:53:40 ICT" skipped="0">
  <testcase classname="testModel.AnswerTest" name="getNoiDungTest_TC08" time="0.001"/>
  <system-out/>
  <testcase classname="testModel.AnswerTest" name="setGiaiThichTest_TC_19" time="0.001"/>
  <system-out/>
  <testcase classname="testModel.AnswerTest" name="getGiaiThichTest_TC03" time="0.001"/>
  <system-out/>
  <testcase classname="testModel.AnswerTest" name="setCauhoi_idTest_TC_15" time="0.001">
    <error message="
Method AnswerTest.setCauhoi_idTest_TC_15()[pri:0, instance:testModel.AnswerTest@707194ba] should have thrown an exception of type class java.lang.Exception" type="org.testng.TestException">
      <![CDATA[org.testng.TestException: 
Method AnswerTest.setCauhoi_idTest_TC_15()[pri:0, instance:testModel.AnswerTest@707194ba] should have thrown an exception of type class java.lang.Exception
at org.testng.internal.ExpectedExceptionsHolder.noException(ExpectedExceptionsHolder.java:82)
at org.testng.internal.TestInvoker.considerExceptions(TestInvoker.java:749)
at org.testng.internal.TestInvoker.invokeMethod(TestInvoker.java:634)
at org.testng.internal.TestInvoker.invokeTestMethod(TestInvoker.java:173)
at org.testng.internal.MethodRunner.runInSequence(MethodRunner.java:46)
at org.testng.internal.TestInvoker$MethodInvocationAgent.invoke(TestInvoker.java:824)
at org.testng.internal.TestInvoker.invokeTestMethods(TestInvoker.java:146)
at org.testng.internal.TestMethodWorker.invokeTestMethods(TestMethodWorker.java:146)
at org.testng.internal.TestMethodWorker.run(TestMethodWorker.java:128)
at java.base/java.util.ArrayList.forEach(ArrayList.java:1511)
at org.testng.TestRunner.privateRun(TestRunner.java:794)
at org.testng.TestRunner.run(TestRunner.java:596)
at org.testng.SuiteRunner.runTest(SuiteRunner.java:377)
at org.testng.SuiteRunner.runSequentially(SuiteRunner.java:371)
at org.testng.SuiteRunner.privateRun(SuiteRunner.java:332)
at org.testng.SuiteRunner.run(SuiteRunner.java:276)
at org.testng.SuiteRunnerWorker.runSuite(SuiteRunnerWorker.java:53)
at org.testng.SuiteRunnerWorker.run(SuiteRunnerWorker.java:96)
at org.testng.TestNG.runSuitesSequentially(TestNG.java:1212)
at org.testng.TestNG.runSuitesLocally(TestNG.java:1134)
at org.testng.TestNG.runSuites(TestNG.java:1063)
at org.testng.TestNG.run(TestNG.java:1031)
at org.testng.remote.AbstractRemoteTestNG.run(AbstractRemoteTestNG.java:115)
at org.testng.remote.RemoteTestNG.initAndRun(RemoteTestNG.java:251)
at org.testng.remote.RemoteTestNG.main(RemoteTestNG.java:77)
]]>
    </error>
  </testcase> <!-- setCauhoi_idTest_TC_15 -->
  <system-out/>
  <testcase classname="testModel.AnswerTest" name="getGiaiThichTest_TC04" time="0.002"/>
  <system-out/>
  <testcase classname="testModel.AnswerTest" name="setFlagTest_TC_17" time="0.001"/>
  <system-out/>
  <testcase classname="testModel.AnswerTest" name="getCauhoi_idTest_TC_02" time="0.002"/>
  <system-out/>
  <testcase classname="testModel.AnswerTest" name="setNoiDungTest_TC_22" time="0.001"/>
  <system-out/>
  <testcase classname="testModel.AnswerTest" name="setTrangThaiTest" time="0.000"/>
  <system-out/>
  <testcase classname="testModel.AnswerTest" name="setIdTest_TC_20" time="0.001"/>
  <system-out/>
  <testcase classname="testModel.AnswerTest" name="isFlagTest_TC_11" time="0.001"/>
  <system-out/>
  <testcase classname="testModel.AnswerTest" name="setIdTest_TC_21" time="0.000">
    <error message="
Method AnswerTest.setIdTest_TC_21()[pri:0, instance:testModel.AnswerTest@707194ba] should have thrown an exception of type class java.lang.Exception" type="org.testng.TestException">
      <![CDATA[org.testng.TestException: 
Method AnswerTest.setIdTest_TC_21()[pri:0, instance:testModel.AnswerTest@707194ba] should have thrown an exception of type class java.lang.Exception
at org.testng.internal.ExpectedExceptionsHolder.noException(ExpectedExceptionsHolder.java:82)
at org.testng.internal.TestInvoker.considerExceptions(TestInvoker.java:749)
at org.testng.internal.TestInvoker.invokeMethod(TestInvoker.java:634)
at org.testng.internal.TestInvoker.invokeTestMethod(TestInvoker.java:173)
at org.testng.internal.MethodRunner.runInSequence(MethodRunner.java:46)
at org.testng.internal.TestInvoker$MethodInvocationAgent.invoke(TestInvoker.java:824)
at org.testng.internal.TestInvoker.invokeTestMethods(TestInvoker.java:146)
at org.testng.internal.TestMethodWorker.invokeTestMethods(TestMethodWorker.java:146)
at org.testng.internal.TestMethodWorker.run(TestMethodWorker.java:128)
at java.base/java.util.ArrayList.forEach(ArrayList.java:1511)
at org.testng.TestRunner.privateRun(TestRunner.java:794)
at org.testng.TestRunner.run(TestRunner.java:596)
at org.testng.SuiteRunner.runTest(SuiteRunner.java:377)
at org.testng.SuiteRunner.runSequentially(SuiteRunner.java:371)
at org.testng.SuiteRunner.privateRun(SuiteRunner.java:332)
at org.testng.SuiteRunner.run(SuiteRunner.java:276)
at org.testng.SuiteRunnerWorker.runSuite(SuiteRunnerWorker.java:53)
at org.testng.SuiteRunnerWorker.run(SuiteRunnerWorker.java:96)
at org.testng.TestNG.runSuitesSequentially(TestNG.java:1212)
at org.testng.TestNG.runSuitesLocally(TestNG.java:1134)
at org.testng.TestNG.runSuites(TestNG.java:1063)
at org.testng.TestNG.run(TestNG.java:1031)
at org.testng.remote.AbstractRemoteTestNG.run(AbstractRemoteTestNG.java:115)
at org.testng.remote.RemoteTestNG.initAndRun(RemoteTestNG.java:251)
at org.testng.remote.RemoteTestNG.main(RemoteTestNG.java:77)
]]>
    </error>
  </testcase> <!-- setIdTest_TC_21 -->
  <system-out/>
  <testcase classname="testModel.AnswerTest" name="getIdTest_TC05" time="0.001"/>
  <system-out/>
  <testcase classname="testModel.AnswerTest" name="isTrangThaiTest_TC_12" time="0.001"/>
  <system-out/>
  <testcase classname="testModel.AnswerTest" name="setGiaiThichTest_TC_18" time="0.003"/>
  <system-out/>
  <testcase classname="testModel.AnswerTest" name="setCauhoi_idTest_TC_16" time="0.001"/>
  <system-out/>
  <testcase classname="testModel.AnswerTest" name="getIdTest_TC06" time="0.001"/>
  <system-out/>
  <testcase classname="testModel.AnswerTest" name="getNoiDungTest_TC07" time="0.001"/>
  <system-out/>
  <testcase classname="testModel.AnswerTest" name="getCauhoi_idTest_TC_01" time="0.005"/>
  <system-out/>
  <testcase classname="testModel.AnswerTest" name="isFlagTest_TC_10" time="0.001"/>
  <system-out/>
  <testcase classname="testModel.AnswerTest" name="setNoiDungTest_TC_23" time="0.001"/>
  <system-out/>
  <testcase classname="testModel.AnswerTest" name="setCauhoi_idTest_TC_14" time="0.003">
    <failure message="expected [0] but found [2]" type="java.lang.AssertionError">
      <![CDATA[java.lang.AssertionError: expected [0] but found [2]
at org.testng.Assert.fail(Assert.java:99)
at org.testng.Assert.failNotEquals(Assert.java:1037)
at org.testng.Assert.assertEqualsImpl(Assert.java:140)
at org.testng.Assert.assertEquals(Assert.java:122)
at org.testng.Assert.assertEquals(Assert.java:907)
at org.testng.Assert.assertEquals(Assert.java:917)
at testModel.AnswerTest.setCauhoi_idTest_TC_14(AnswerTest.java:102)
at java.base/jdk.internal.reflect.NativeMethodAccessorImpl.invoke0(Native Method)
at java.base/jdk.internal.reflect.NativeMethodAccessorImpl.invoke(NativeMethodAccessorImpl.java:64)
at java.base/jdk.internal.reflect.DelegatingMethodAccessorImpl.invoke(DelegatingMethodAccessorImpl.java:43)
at java.base/java.lang.reflect.Method.invoke(Method.java:564)
at org.testng.internal.MethodInvocationHelper.invokeMethod(MethodInvocationHelper.java:133)
at org.testng.internal.TestInvoker.invokeMethod(TestInvoker.java:598)
at org.testng.internal.TestInvoker.invokeTestMethod(TestInvoker.java:173)
at org.testng.internal.MethodRunner.runInSequence(MethodRunner.java:46)
at org.testng.internal.TestInvoker$MethodInvocationAgent.invoke(TestInvoker.java:824)
at org.testng.internal.TestInvoker.invokeTestMethods(TestInvoker.java:146)
at org.testng.internal.TestMethodWorker.invokeTestMethods(TestMethodWorker.java:146)
at org.testng.internal.TestMethodWorker.run(TestMethodWorker.java:128)
at java.base/java.util.ArrayList.forEach(ArrayList.java:1511)
at org.testng.TestRunner.privateRun(TestRunner.java:794)
at org.testng.TestRunner.run(TestRunner.java:596)
at org.testng.SuiteRunner.runTest(SuiteRunner.java:377)
at org.testng.SuiteRunner.runSequentially(SuiteRunner.java:371)
at org.testng.SuiteRunner.privateRun(SuiteRunner.java:332)
at org.testng.SuiteRunner.run(SuiteRunner.java:276)
at org.testng.SuiteRunnerWorker.runSuite(SuiteRunnerWorker.java:53)
at org.testng.SuiteRunnerWorker.run(SuiteRunnerWorker.java:96)
at org.testng.TestNG.runSuitesSequentially(TestNG.java:1212)
at org.testng.TestNG.runSuitesLocally(TestNG.java:1134)
at org.testng.TestNG.runSuites(TestNG.java:1063)
at org.testng.TestNG.run(TestNG.java:1031)
at org.testng.remote.AbstractRemoteTestNG.run(AbstractRemoteTestNG.java:115)
at org.testng.remote.RemoteTestNG.initAndRun(RemoteTestNG.java:251)
at org.testng.remote.RemoteTestNG.main(RemoteTestNG.java:77)
]]>
    </failure>
  </testcase> <!-- setCauhoi_idTest_TC_14 -->
  <system-out/>
  <testcase classname="testModel.AnswerTest" name="isTrangThaiTest_TC_13" time="0.001"/>
  <system-out/>
</testsuite> <!-- testModel.AnswerTest -->
